Workbook
Name AÑO_FISCAL: 'IR-1'!$AD$7
Name NOMBRE: 'IR-1'!$J$11
Name RNC: 'IR-1'!$H$11

Sheet Anexo RG
E4: DIRECCIÓN GENERAL DE IMPUESTOS INTERNOS | X4: Anexo RG
E5: REGISTRO DE GASTOS EDUCATIVOS
C7: Versión 2018 | X7: AÑO FISCAL
X8: =AÑO_FISCAL -> 0
D10: DATOS PERSONALES DECLARANTE
D11: RNC/CÉDULA | L11: NOMBRE(S) Y APELLIDO(S)
D12: =RNC -> 0 | L12: =NOMBRE -> 0
C15: I. -GASTOS EN EDUCACIÓN
D16: RNC/CEDULA | J16: TIPO ID | L16: NIVEL | N16: NCF | P16: FECHA | R16: VALOR | W16: DEPENDIENTE
C17: 1
C18: 2
C19: 3
C20: 4
C21: 5
C22: 6
C23: 7
C24: 8
C25: 9
C26: 10
C27: 11
C28: 12
... C46: 30
O47: 31 | P47: TOTAL | R47: =SUM(R17:R46) -> 0

Sheet Anexo RD
W4: Anexo RD
G5: DIRECCIÓN GENERAL DE IMPUESTOS INTERNOS
G6: REGISTRO DE DEPENDIENTES | W6: AÑO FISCAL
C7: Versión 2018 | W7: =AÑO_FISCAL -> 0
D10: DATOS PERSONALES DECLARANTE
D11: RNC/CÉDULA | L11: NOMBRE(S) Y APELLIDO(S)
D12: =RNC -> 0 | L12: =NOMBRE -> 0
C15: I. -RELACIÓN DE DEPENDIENTES
D16: FECHA NACIMIENTO | J16: CEDULA | L16: PRIMERO APELLIDO | N16: SEGUNDO APELLIDO | Q16: PRIMER NOMBRE | T16: SEGUNDO NOMBRE | W16: RELACIÓN
C17: 1 | Z17: Contribuyente
C18: 2 | Z18: Hijo (a)
C19: 3
C20: 4
C21: 5
C22: 6
C23: 7
C24: 8
C25: 9
C26: 10
C27: 11
C28: 12
C29: 13
C30: 14
... C41: 25

Sheet Anexo B
K3: Anexo B
E4: DIRECCION GENERAL DE IMPUESTOS INTERNOS
E5: ESTADO DE RESULTADOS | K5: AÑO FISCAL
K6: =AÑO_FISCAL -> 0
C7: Version 2018
D9: DATOS PERSONALES DECLARANTE
D10: RNC/CÉDULA | H10: NOMBRE(S) Y APELLIDO(S)
D11: =RNC -> 0 | H11: =NOMBRE -> 0
C14: I. | D14: 1 | E14: INGRESOS POR VENTAS BIENES LOCALES | I14: +
C15: INGRESOS | D15: =+D14+1 -> 2 | E15: INGRESOS POR EXPORTACIONES | I15: +
D16: =+D15+1 -> 3 | E16: INGRESOS POR PRESTACION DE SERVICIOS | I16: +
D17: =+D16+1 -> 4 | E17: INGRESOS POR HONORARIOS PROFESIONALES | I17: +
D18: =+D17+1 -> 5 | E18: INGRESOS POR ALQUILERES | I18: +
D19: =+D18+1 -> 6 | E19: OTROS INGRESOS | I19: +
D20: =+D19+1 -> 7 | E20: DEVOLUCIONES S/VENTAS | I20: -
D21: =+D20+1 -> 8 | E21: DESCUENTOS S/VENTAS | I21: -
D22: =+D21+1 -> 9 | E22: INGRESOS POR SALARIOS | I22: +
D23: =+D22+1 -> 10 | E23: INTERESES POR INVERSIONES FINANCIERAS EN INSTITUCIONES REGULADAS POR LAS AUTORIDADES MONETARIAS | I23: +
D24: =+D23+1 -> 11 | E24: INTERESES POR INVERSIONES FINANCIERAS DE INSTITUCIONES NO REGULADAS POR LAS AUTORIDADES MONETARIAS | I24: +
D25: =+D24+1 -> 12 | E25: VENTAS DE BIENES DE CAPITAL | I25: +
D26: =+D25+1 -> 13 | E26: INGRESOS POR DIVIDENDOS | I26: +
D27: =D26+1 -> 14 | E27: TOTAL INGRESOS (Casillas 1+2+3+4+5+6-7-8+9+10+11+12+13) | K27: = | L27: =J14+J15+J16+J17+J18+J19-J20-J21+J22+J23+J24+J25+J26 -> 0
C29: II. | D29: =+D27+1 -> 15 | E29: INVENTARIO INICIAL | I29: +
C30: COSTOS | D30: =+D29+1 -> 16 | E30: COMPRAS LOCALES | I30: +
D31: =+D30+1 -> 17 | E31: COMPRAS EN EL EXTERIOR (IMPORTACIONES) | I31: +
D32: =+D31+1 -> 18 | E32: ITBIS LLEVADO AL COSTO | I32: +
D33: =+D32+1 -> 19 | E33: INVENTARIO FINAL | I33: -
D34: =+D33+1 -> 20 | E34: TOTAL COSTO DE VENTA (Casillas 15+16+17+18-19) | K34: = | L34: =+J29+J30+J31+J32-J33 -> 0
C36: III. | D36: =+D34+1 -> 21 | E36: SUELDOS Y SALARIOS | I36: +
C37: GASTOS DE PERSONAL | D37: =+D36+1 -> 22 | E37: RETRIBUCIONES COMPLEMENTARIAS | I37: +
D38: =+D37+1 -> 23 | E38: SEGUROS | I38: +
D39: =+D38+1 -> 24 | E39: APORTACION SEGURIDAD SOCIAL | I39: +
D40: =+D39+1 -> 25 | E40: APORTE INFOTEP | I40: +
D41: =+D40+1 -> 26 | E41: OTROS GASTOS DE PERSONAL | I41: +
D42: =+D41+1 -> 27 | E42: TOTAL GASTOS DE PERSONAL (Sumar Casillas 21+22+23+24+25+26) | K42: = | L42: =SUM(J36:K41) -> 0
C44: IV. | D44: =+D42+1 -> 28 | E44: HONORARIOS POR SERVICIOS PROFESIONALES | I44: +
C45: GASTOS POR TRABAJOS, SUMINISTROS Y SERVICIOS | D45: =+D44+1 -> 29 | E45: HONORARIOS POR SERVICIOS DEL EXTERIOR (LEY No. 392-07) | I45: +
D46: =+D45+1 -> 30 | E46: HONORARIOS POR SERVICIOS DEL EXTERIOR (PERSONAS FISICAS Y MORALES) | I46: +
D47: =+D46+1 -> 31 | E47: FACTURAS DE ENERGIA ELECTRICA | I47: +
D48: =+D47+1 -> 32 | E48: FACTURAS TELEFONICAS (Teléfonos Fijos y Móviles) | I48: +
...

Sheet Anexo A
U4: Anexo A
F5: DIRECCIÓN GENERAL DE IMPUESTOS INTERNOS
F6: DATOS COMPLEMENTARIOS | T6: AÑO FISCAL
T7: =AÑO_FISCAL -> 0
C8: Versión 2018
D10: DATOS PERSONALES DECLARANTE
D11: RNC/CÉDULA | H11: NOMBRE(S) Y APELLIDO(S)
D12: =RNC -> 0 | H12: =NOMBRE -> 0
C15: I. | E15: DETALLE DE LOS BIENES | R15: CANTIDAD | U15: MONTO
C16: PATRIMONIO | E16: 1 | F16: INMUEBLES URBANOS: SOLARES
E17: =+E16+1 -> 2 | F17: INMUEBLES URBANOS: MEJORAS
E18: =+E17+1 -> 3 | F18: INMUEBLES RURALES: TERRENOS
E19: =+E18+1 -> 4 | F19: MEJORAS, INSTALACIONES CONTENIDAS TERRENOS RURALES
E20: =+E19+1 -> 5 | F20: EXISTENCIA DE GANADO VACUNO, PORCINO, AVÍCOLA, ETC.
E21: =+E20+1 -> 6 | F21: EXISTENCIA DE PRODUCTOS AGRÍCOLAS Y FORESTALES
E22: =+E21+1 -> 7 | F22: CAPITAL INVERTIDO COMO DUEÑO O SOCIO EN NEGOCIOS
E23: =+E22+1 -> 8 | F23: ACCIONES QUE POSEEN EN COMPAÑÍAS (Valor nominal)
E24: =+E23+1 -> 9 | F24: TÍTULOS, BONOS, OTROS DEPÓSITOS EN BANCOS O EN SU PODER
E25: =+E24+1 -> 10 | F25: CRÉDITOS HIPOTECARIOS
E26: =+E25+1 -> 11 | F26: VEHÍCULOS MOTOR: AUTOMÓVILES
E27: =+E26+1 -> 12 | F27: MOBILIARIO DE OFICINA, CONSULTORIO, BUFETES, ETC.
E28: =+E27+1 -> 13 | F28: MOBILIARIO DE LA CASA
... E31: =+E30+1 -> 16 | F31: OTROS
E32: =+E31+1 -> 17 | F32: TOTAL DE BIENES ACUMULADOS EN EL AÑO (Sumar casillas 1 hasta 16) | U32: =+SUM(U16:U31) -> 0
E33: =+E32+1 -> 18 | F33: DEUDAS POR PRESTAMOS HIPOTECARIOS
E34: =+E33+1 -> 19 | F34: DEUDAS POR PRESTAMOS PRENDARIOS
E35: =+E34+1 -> 20 | F35: OTRAS DEUDAS
E36: =+E35+1 -> 21 | F36: PATRIMONIO NETO DEL AÑO (Casillas 17-18-19-20) | U36: =U32-U33-U34-U35 -> 0
C38: II. | E38: DETALLES DE RETENCIONES (Anexar certificaciones) | U38: MONTO
C39: RETENCIONES | E39: =+E36+1 -> 22 | F39: RETENCIONES EFECTUADAS ENTIDADES ESTATALES (Viene del Formato de Envío 623)
E40: =E39+1 -> 23 | F40: RETENCIONES POR SALARIOS
E41: =E40+1 -> 24 | F41: RETENCIONES POR HONORARIOS
E42: =E41+1 -> 25 | F42: RETENCIONES POR ALQUILER
E43: =E42+1 -> 26 | F43: RETENCIONES POR INTERESES PERCIBIDOS
E44: =E43+1 -> 27 | F44: OTRAS RETENCIONES
E45: =E44+1 -> 28 | F45: TOTAL DE RETENCIONES (Sumar casillas 22 hasta 27) | U45: =SUM(U39:U44) -> 0
C46: =IF(AND('Anexo B'!J22<=U40,U40>0),"La Casilla 10 'Ingresos por Salarios' del Anexo B debe ser superior a la Casilla 23 'Retenciones por Salarios'.",0) -> 0

Sheet IR-1
G5: DIRECCIÓN GENERAL DE IMPUESTOS INTERNOS | AD5: IR-1
G6: DECLARACIÓN JURADA DE IMPUESTO SOBRE LA RENTA PARA LAS PERSONAS FÍSICAS
AB7: AÑO FISCAL
C8: Versión 2018
C10: I. | H10: RNC/CÉDULA | J10: NOMBRE(S) Y APELLIDO(S) | S10: NOMBRE COMERCIAL
C11: DATOS PERSONALES DECLARANTE
H12: TELÉFONO | J12: CORREO ELECTRÓNICO | S12: CONTABILIDAD ORGANIZADA | AB12: TIPO DE DECLARACIÓN
S13: SI | AB13: NORMAL
C16: II. | G16: A. | H16: INGRESOS (Viene de la casilla 14 "Total de Ingresos" del Anexo B) | AA16: = | AB16: A | AC16: =+'Anexo B'!L27 -> 0
C17: RENTA NETA IMPONIBLE | G17: 1 | H17: BENEFICIO O PERDIDA NETA ANTES DEL IMPUESTO (Viene de la casilla 67 "Beneficio (Perdida) del Ejerc. Antes de ISR" del Anexo B) | AA17: = | AB17: 1 | AC17: =+'Anexo B'!L90 -> 0
G18: 2 | H18: GASTOS NO ADMITIDOS | T18: + | U18: 2
G19: 3 | H19: INGRESOS EXENTOS (Anexar Certificación) | T19: - | U19: 3
G20: 4 | H20: INGRESOS POR DIVIDENDOS (Viene de la casilla 13 "Ingresos por Dividendos" del Anexo B) | T20: - | U20: 4 | V20: =+'Anexo B'!J26 -> 0
G21: 5 | H21: RENTA NETA (O PERDIDA) (Casillas 1+2-3-4) | AA21: = | AB21: 5 | AC21: =AC17+V18-V19-V20 -> 0
G22: 6 | H22: EXENCIÓN CONTRIBUTIVA (Solo aplica para los que no reportan costos o gastos) | T22: - | U22: 6 | V22: =ABS(IF(('Anexo B'!L34+'Anexo B'!L42+'Anexo B'!L52+'Anexo B'!L54+'Anexo B'!L63+'Anexo B'!L70+'Anexo B'!L75+'Anexo B'!L84+'Anexo B'!L88)<=0,(416220),0)) -> 416220 | AC22: =IF(AC21-V22>0,AC21-V22,0) -> 0
G23: 7 | H23: EXENCIÓN GASTOS EN EDUCACIÓN (No exceder 10% de las casillas 5-6 y el 25% de la Exención Contributiva) | T23: - | U23: 7 | V23: =IF((IF('Anexo RG'!R47>(AC22*0.1),AC22*0.1,'Anexo RG'!R47))>=AC23*0.25,AC23*0.25,IF('Anexo RG'!R47>(AC22*0.1),AC22*0.1,'Anexo RG'!R47)) -> 0 | AC23: 416220
G24: 8 | H24: GANANCIA DE CAPITAL POR VENTAS DE ACCIONES | T24: + | U24: 8
G25: 9 | H25: GANANCIA DE CAPITAL POR VENTA Y/O APORTE EN NATURALEZA DE INMUEBLES | T25: + | U25: 9
G26: 10 | H26: RENTA NETA IMPONIBLE (Casillas 5-6-7+8+9, si aplica) | AA26: = | AB26: 10 | AC26: =IF(AC21-V22-V23+V24+V25>0,AC21-V22-V23+V24+V25,0) -> 0
C28: III. | G28: 11 | H28: IMPUESTO LIQUIDADO (Aplica tasa sobre casilla 10) | AA28: = | AB28: 11 | AC28: =ABS(IF(AND(AC26<=0,V22>0),0,IF(AND(AC26<=208109,V22>0),0.15*AC26,IF(AND(AC26<=450903,V22>0),31216.35 +(0.2*(AC26-208109)),IF(AND(AC26>=450903,V22>0), 79775.15 +(0.25*(AC26-450903)),IF(AC26<=624329,0.15*AC26,IF(AC26<=867123,93649.35 +(0.2*(AC26-624329)),IF(AC26>867123, 142208.15 +(0.25*(AC26-867123)))))))))) -> 0
C29: LIQUIDACIÓN | G29: 12 | H29: ANTICIPOS PAGADOS | T29: - | U29: 12
G30: 13 | H30: RETENCIONES (Viene las Casillas 28 del Anexo A) | T30: - | U30: 13 | V30: =+'Anexo A'!U45 -> 0
G31: 14 | H31: OTROS PAGOS | T31: - | U31: 14
G32: 15 | H32: SALDO A FAVOR EJERCICIO ANTERIOR | T32: - | U32: 15
G33: 16 | H33: DIFERENCIA A PAGAR (Casillas 11-12-13-14-15 si es positivo) | AA33: = | AB33: 16 | AC33: =IF((AC28-V29-V30-V31-V32)>0,(AC28-V29-V30-V31-V32),0) -> 0
G34: 17 | H34: SALDO A FAVOR (Casillas 11-12-13-14-15 si es negativo) | T34: = | U34: 17 | V34: =ABS(IF((AC28-V29-V30-V31-V32)<0,(AC28-V29-V30-V31-V32),0)) -> 0
G35: 18 | H35: MORA EN DECLARACIÓN TARDÍA | L35: % sobre la casilla 16. | T35: + | U35: 18 | V35: =AC33*K35% -> 0
G36: 19 | H36: MORA EN ANTICIPOS NO PAGADOS | T36: + | U36: 19
G37: 20 | H37: INTERÉS INDEMNIZATORIO | L37: % sobre la casilla 16. | T37: + | U37: 20 | V37: =AC33*K37% -> 0
G38: 21 | H38: INTERÉS INDEMNIZATORIO POR ANTICIPOS NO PAGADOS | T38: + | U38: 21
G39: 22 | H39: TOTAL A PAGAR (Sumar casillas 16+18+19+20+21) | AA39: = | AB39: 22 | AC39: =AC33+V35+V36+V37+V38 -> 0
C41: IV.
C42: PARA USO DE LA DGII | H42: FECHA DE PRESENTACIÓN | M42: FECHA DE PRORROGA
H44: FECHA DE PAGO | M44: FECHA ACUSE NOTIFICACIÓN INICIAL
C47: V. JURAMENTO DEL DECLARANTE | L47: VI. AUTORIZACIÓN DE PRESENTACIÓN | AA47: VII. CONSTANCIA DE PAGO
L48: Autorizo a la siguiente persona a representarme ante esta Dirección General, en la presentación y trámite de esta Declaración Jurada. | AA48: FIRMA Y SELLO
C49: Yo
C50: en calidad de
C51: por la presente afirmo bajo juramento que los datos consignados en la presente declaración de renta son correctos y completos y que no he omitido ni falseado dato alguno que la misma deba contener, siendo en consecuencia todo su contenido la fiel expresión de la verdad. | L51: Apellidos
L53: Nombres
...

Sheet Anticipos
F2: Versión 2018
D3: DIRECCION GENERAL DE IMPUESTOS INTERNOS
D4: DECLARACION JURADA DE IMPUESTO SOBRE LA RENTA PARA LAS PERSONAS FISICAS
C6: CALCULO DE ANTICIPOS
C8: CALCULO RENTA NETA
C9: RENTA NETA IMPONIBLE (Casilla 10 del IR-1) | E9: = | F9: =+'IR-1'!AC26 -> 0
C10: GANANCIA DE CAPITAL POR VENTAS DE ACCIONES (Casilla 8 del IR-1) | E10: - | F10: =+'IR-1'!V24 -> 0
C11: GANANCIA DE CAPITAL POR VENTA Y/O APORTE EN NATURALEZA DE INMUEBLES (Casilla 9 del IR-1) | E11: - | F11: =+'IR-1'!V25 -> 0
C12: RENTA NETA IMPONIBLE SUJETA AL PAGO DE ANTICIPOS | E12: = | F12: =IF(F9-F11-F10<0,0,F9-F11-F10) -> 0
C14: EXENCIÓN CONTRIBUTIVA (Casilla 6 del IR-1) | E14: = | F14: =+'IR-1'!V22 -> 416220
C15: IMPUESTO LIQUIDADO SUJETO AL PAGO DE ANTICIPOS (Aplica tasa a la Renta Neta Imponible) | E15: = | F15: =ABS(IF(AND(F12<=0,F14>0),0,IF(AND(F12<=208109,F14>0),0.15*F12,IF(AND(F12<=450903,F14>0),31216.35 +(0.2*(F12-208109)),IF(AND(F12>=450903,F14>0), 79775.15 +(0.25*(F12-450903)),IF(F12<=624329,0.15*F12,IF(F12<=867123,93649.35 +(0.2*(F12-624329)),IF(F12>867123, 142208.15 +(0.25*(F12-867123)))))))))) -> 0
C16: TOTAL DE RETENCIONES (Casilla 13 del IR-1) | E16: - | F16: ='IR-1'!V30 -> 0
C17: IMPUESTO LIQUIDADO NETO SUJETO AL PAGO DE ANTICIPOS | E17: = | F17: =IF(F15-F16<=0,0,F15-F16) -> 0
C20: ANTICIPOS GENERADOS
C21: JUNIO | E21: + | F21: =IF(F17>1000,F17*50%,0) -> 0
C22: SEPTIEMBRE | E22: + | F22: =IF(F17>1000,F17*30%,0) -> 0
C23: DICIEMBRE | E23: + | F23: =IF(F17>1000,F17*20%,0) -> 0
C24: TOTAL | E24: = | F24: =SUM(F21:F23) -> 0
